2016-04-21 12:58:05,740 (3169/MainThread) pgcli.main ERROR - traceback: 'Traceback (most recent call last):\n  File "/usr/local/Cellar/pgcli/0.20.1/libexec/lib/python2.7/site-packages/pgcli/main.py", line 235, in connect\n    raise e\nOperationalError: could not connect to server: No such file or directory\n\tIs the server running locally and accepting\n\tconnections on Unix domain socket "/tmp/.s.PGSQL.5432"?\n\n'
